<?xml version="1.0"?>
<robot xmlns:xacro="http://www.ros.org/wiki/xacro" name="bcr_bot">

    <xacro:property name="base_width" value="0.4572"/>
    <xacro:property name="base_length" value="0.5588"/>
    <xacro:property name="base_height" value="0.0762"/>
  
    <xacro:property name="wheel_radius" value="0.05"/>
    <xacro:property name="wheel_width" value="0.04"/>
    <xacro:property name="wheel_ygap" value="0.0127"/>
    <xacro:property name="wheel_zoff" value="0.0381"/>
    <xacro:property name="wheel_xoff" value="0.215"/>

    <!-- ............................... LOAD MACROS ................................. -->

    <xacro:include filename="$(find trr_robot)/description/gz.xacro"/>

    <!-- ................................ BASE LINK .................................. -->
    <link name="base_footprint"></link>

    <joint name="base_joint" type="fixed">
        <parent link="base_footprint"/>
        <child link="base_link"/>
        <origin xyz="0.0 0.0 0.075" rpy="0 0 0"/>
    </joint>

    <link name="base_link">
        <visual>
            <geometry>
                <box size="${base_length} ${base_width} ${base_height}"/>
            </geometry>
            <material name="Cyan">
                <color rgba="0 1.0 1.0 1.0"/>
            </material>
        </visual>
        <collision>
            <origin xyz="0 0 0.05" rpy="0 0 0"/>
            <geometry>
                <box size="${base_length} ${base_width} ${base_height}"/>
            </geometry>
        </collision>
        <inertial>
            <origin xyz="0 0 0.05" rpy="0 0 0"/>
            <mass value="12"/>
            <inertia ixx="2.26" ixy="0.0" ixz="0.0" iyy="6.26" iyz="0.0" izz="8.5"/>
        </inertial>
    </link>

    <!-- ................................ WHEELS ..................................... -->
    <xacro:macro name="wheel" params="prefix x_reflect y_reflect">
        <link name="${prefix}_link">
            <visual>
                <origin xyz="0 0 0" rpy="${pi/2} 0 0"/>
                <geometry>
                    <cylinder radius="${wheel_radius}" length="${wheel_width}"/>
                </geometry>
                <material name="Gray">
                <color rgba="0.5 0.5 0.5 1.0"/>
                </material>
            </visual>
            <collision>
                <origin xyz="0 0 0" rpy="${pi/2} 0 0"/>
                <geometry>
                    <cylinder radius="${wheel_radius}" length="${wheel_width}"/>
                </geometry>
            </collision>
            <inertial>
                <origin xyz="0 0 0"/>
                <mass value="0.05"/>
                <inertia ixx="0.00001" ixy="0" ixz="0" iyy="0.000018" iyz="0" izz="0.00001"/>
            </inertial>
        </link>

        <joint name="${prefix}_joint" type="continuous">
            <parent link="base_link"/>
            <child link="${prefix}_link"/>
            <origin xyz="${x_reflect*wheel_xoff} ${y_reflect*(base_width/2+wheel_ygap)} ${-wheel_zoff}" rpy="0 0 0"/>
            <axis xyz="0 1 0"/>
        </joint>
    </xacro:macro>

    <xacro:wheel prefix="drivewhl_fl" x_reflect="1" y_reflect="1" />
    <xacro:wheel prefix="drivewhl_fr" x_reflect="1" y_reflect="-1" />
    <xacro:wheel prefix="drivewhl_rl" x_reflect="-1" y_reflect="1" />
    <xacro:wheel prefix="drivewhl_rr" x_reflect="-1" y_reflect="-1" />

    <!-- Depth CAMERA -->

    <link name="depth_camera">
        <visual>
            <geometry>
                <box size="0.010 0.03 0.03"/>
            </geometry>
            <material name="Cyan">
                <color rgba="0 1.0 1.0 1.0"/>
            </material>
        </visual>
    </link>

    <joint name="depth_camera_joint" type="fixed">
        <origin xyz="0.305 0 0.08" rpy="0 0 0"/>
        <parent link="base_link"/>
        <child link="depth_camera"/>
    </joint>

    <link name="depth_camera_optical"/>

    <joint name="depth_camera_optical_joint" type="fixed">
        <origin xyz="0 0 0" rpy="${-pi/2} 0 ${-pi/2}"/>
        <parent link="depth_camera"/>
        <child link="depth_camera_optical"/>
    </joint>

</robot>